corpus/scenarios/best-price-first.txt
# A market order sweeps the book best price first, whatever order the levels were created in.

INSTRUMENT tick=5 lot=1 scale=4 min=1 max=1000000 band=500 open=100000 alloc=PRICE_TIME

SESSION    CONTINUOUS
STATE      CONTINUOUS

NEW        BUY  LIMIT GTC 99990 10
ACCEPTED   #1
RESTED     #1 BUY 99990 10

NEW        BUY  LIMIT GTC 100000 10
ACCEPTED   #2
RESTED     #2 BUY 100000 10

NEW        BUY  LIMIT GTC 99995 10
ACCEPTED   #3
RESTED     #3 BUY 99995 10

NEW        SELL MARKET IOC - 25
ACCEPTED   #4
EXECUTED   @1 aggressor=#4 resting=#2 100000 10
EXECUTED   @2 aggressor=#4 resting=#3 99995 10
EXECUTED   @3 aggressor=#4 resting=#1 99990 5
